<?xml version="1.0" ?>
<!-- =================================================================================== -->
<!-- |    This document was autogenerated by xacro from igus_axis_standalone.urdf.xacro | -->
<!-- |    EDITING THIS FILE BY HAND IS NOT RECOMMENDED                                 | -->
<!-- =================================================================================== -->
<!-- Revolute-Revolute Manipulator -->
<!--
Copied and modified from ROS1 example -
https://github.com/ros-simulation/gazebo_ros_demos/blob/kinetic-devel/rrbot_description/urdf/rrbot.xacro
-->
<robot name="2dof_robot">
  <!-- Used for fixing robot -->


  <!-- Square dimensions (widthxwidth) of beams -->
  <!-- Link 3-->
  <!-- Space btw top of beam and the each joint -->
  <!-- Base Link -->
  <link name="base_link">
    <collision>
      <origin rpy="0 0 0" xyz="0 0 1.25"/>
      <geometry>
        <box size="0.2 0.6 2.5"/>
      </geometry>
    </collision>
    <visual>
      <origin rpy="0 0 0" xyz="0 0 1.25"/>
      <geometry>
        <box size="0.2 0.6 2.5"/>
      </geometry>
    </visual>
    <inertial>
      <origin rpy="0 0 0" xyz="0 0 1.25"/>
      <mass value="1"/>
      <inertia ixx="0.5308333333333333" ixy="0.0" ixz="0.0" iyy="0.5308333333333333" iyz="0.0" izz="0.019999999999999997"/>
    </inertial>
  </link>
  <joint name="axis_joint1" type="prismatic">
    <parent link="base_link"/>
    <child link="axis_link1"/>
    <origin rpy="0 0 0" xyz="0 0.3 0.2"/>
    <axis xyz="0 0 1"/>
    <dynamics damping="0.7"/>
    <limit effort="10" lower="0" upper="2" velocity=".05"/>
  </joint>
  <!-- Middle Link -->
  <link name="axis_link1">
    <collision>
      <origin rpy="0 0 0" xyz="0 0 0"/>
      <geometry>
        <box size="0.2 0.05 0.4"/>
      </geometry>
    </collision>
    <visual>
      <origin rpy="0 0 0" xyz="0 0 0"/>
      <geometry>
        <box size="0.2 0.05 0.4"/>
      </geometry>
    </visual>
    <inertial>
      <origin rpy="0 0 0" xyz="0 0 0"/>
      <mass value="1"/>
      <inertia ixx="0.01416666666666667" ixy="0.0" ixz="0.0" iyy="0.01416666666666667" iyz="0.0" izz="0.001666666666666667"/>
    </inertial>
  </link>
  <joint name="axis_finaljoint" type="fixed">
    <parent link="axis_link1"/>
    <child link="axis_end_link"/>
    <origin rpy="0 0 0" xyz="0 0 0"/>
    <axis xyz="0 0 1"/>
    <dynamics damping="0.7"/>
    <limit effort="100" lower="0" upper="2" velocity="100"/>
  </joint>
  <!-- Middle Link -->
  <link name="axis_end_link">
    <collision>
      <origin rpy="0 0 0" xyz="0 0 0"/>
      <geometry>
        <box size="0.2 0.05 0.4"/>
      </geometry>
    </collision>
    <visual>
      <origin rpy="0 0 0" xyz="0 0 0"/>
      <geometry>
        <box size="0.2 0.05 0.4"/>
      </geometry>
    </visual>
    <inertial>
      <origin rpy="0 0 0" xyz="0 0 0"/>
      <mass value="1"/>
      <inertia ixx="0.01416666666666667" ixy="0.0" ixz="0.0" iyy="0.01416666666666667" iyz="0.0" izz="0.001666666666666667"/>
    </inertial>
  </link>

</robot>
